
<sdf version='1.9'>
  <world name='Jetracer Warehouse'>
    <gravity>0 0 -9.8</gravity>
    <physics type='ode'>
      <max_step_size>0.01</max_step_size>
      <real_time_factor>1</real_time_factor>
      <max_contacts>10</max_contacts>
      <real_time_update_rate>1000</real_time_update_rate>
    </physics>
    <plugin name='ignition::gazebo::systems::Physics' filename='libignition-gazebo-physics-system.so'/>
    <plugin name='ignition::gazebo::systems::UserCommands' filename='libignition-gazebo-user-commands-system.so'/>
    <plugin name='ignition::gazebo::systems::SceneBroadcaster' filename='libignition-gazebo-scene-broadcaster-system.so'/>
    <plugin name='ignition::gazebo::systems::Imu' filename='ignition-gazebo-imu-system'/>
    <plugin name='ignition::gazebo::systems::Sensors' filename='ignition-gazebo-sensors-system'>
      <render_engine>ogre2</render_engine>
    </plugin>
    <gui fullscreen='false'>
      <plugin name='3D View' filename='GzScene3D'>
        <ignition-gui>
          <title>3D View</title>
          <property type='bool' key='showTitleBar'>false</property>
          <property type='string' key='state'>docked</property>
        </ignition-gui>
        <engine>ogre2</engine>
        <scene>scene</scene>
        <ambient_light>0.4 0.4 0.4</ambient_light>
        <background_color>0.8 0.8 0.8</background_color>
        <camera_pose>13.4 -6.1 2.23 0 0.4 -1.83</camera_pose>
      </plugin>
      <plugin name='World control' filename='WorldControl'>
        <ignition-gui>
          <title>World control</title>
          <property type='bool' key='showTitleBar'>false</property>
          <property type='bool' key='resizable'>false</property>
          <property type='double' key='height'>72</property>
          <property type='double' key='width'>121</property>
          <property type='double' key='z'>1</property>
          <property type='string' key='state'>floating</property>
          <anchors target='3D View'>
            <line own='left' target='left'/>
            <line own='bottom' target='bottom'/>
          </anchors>
        </ignition-gui>
        <play_pause>true</play_pause>
        <step>true</step>
        <start_paused>true</start_paused>
      </plugin>
      <plugin name='World stats' filename='WorldStats'>
        <ignition-gui>
          <title>World stats</title>
          <property type='bool' key='showTitleBar'>false</property>
          <property type='bool' key='resizable'>false</property>
          <property type='double' key='height'>110</property>
          <property type='double' key='width'>290</property>
          <property type='double' key='z'>1</property>
          <property type='string' key='state'>floating</property>
          <anchors target='3D View'>
            <line own='right' target='right'/>
            <line own='bottom' target='bottom'/>
          </anchors>
        </ignition-gui>
        <sim_time>true</sim_time>
        <real_time>true</real_time>
        <real_time_factor>true</real_time_factor>
        <iterations>true</iterations>
      </plugin>
      <plugin name='Transform control' filename='TransformControl'>
        <ignition-gui>
          <property type='bool' key='showTitleBar'>false</property>
          <property key='x' type='double'>0</property>
          <property key='y' type='double'>0</property>
          <property key='width' type='double'>250</property>
          <property key='height' type='double'>50</property>
          <property key='state' type='string'>floating</property>
          <property key='cardBackground' type='string'>#666666</property>
        </ignition-gui>
      </plugin>
      <plugin name='Shapes' filename='Shapes'>
        <ignition-gui>
          <property type='bool' key='showTitleBar'>false</property>
          <property key='x' type='double'>250</property>
          <property key='y' type='double'>0</property>
          <property key='width' type='double'>150</property>
          <property key='height' type='double'>50</property>
          <property key='state' type='string'>floating</property>
          <property key='cardBackground' type='string'>#666666</property>
        </ignition-gui>
      </plugin>
      <plugin name='Screenshot' filename='Screenshot'>
        <ignition-gui>
          <property type='bool' key='showTitleBar'>false</property>
          <property key='x' type='double'>400</property>
          <property key='y' type='double'>0</property>
          <property key='width' type='double'>50</property>
          <property key='height' type='double'>50</property>
          <property key='state' type='string'>floating</property>
          <property key='cardBackground' type='string'>#666666</property>
        </ignition-gui>
      </plugin>
      <plugin name='Component inspector' filename='ComponentInspector'>
        <ignition-gui>
          <property key='x' type='double'>0</property>
          <property key='y' type='double'>0</property>
          <property key='width' type='double'>400</property>
          <property key='height' type='double'>375</property>
          <property key='state' type='string'>docked_collapsed</property>
        </ignition-gui>
      </plugin>
      <plugin name='Entity tree' filename='EntityTree'>
        <ignition-gui>
          <property key='x' type='double'>0</property>
          <property key='y' type='double'>0</property>
          <property key='width' type='double'>400</property>
          <property key='height' type='double'>375</property>
          <property key='state' type='string'>docked_collapsed</property>
        </ignition-gui>
      </plugin>
      <plugin name='Teleop' filename='Teleop'>
        <ignition-gui>
          <property key='x' type='double'>0</property>
          <property key='y' type='double'>0</property>
          <property key='width' type='double'>400</property>
          <property key='height' type='double'>900</property>
          <property key='state' type='string'>docked</property>
        </ignition-gui>
        <topic>/model/tugbot/cmd_vel</topic>
      </plugin>
    </gui>
    <scene>
      <ambient>1 1 1 1</ambient>
      <background>0.3 0.7 0.9 1</background>
      <shadows>false</shadows>
      <grid>false</grid>
    </scene>
    <magnetic_field>6e-06 2.3e-05 -4.2e-05</magnetic_field>
    <atmosphere type='adiabatic'/>
    <model name='ground_plane'>
      <static>true</static>
      <link name='link'>
        <collision name='collision'>
          <geometry>
            <plane>
              <normal>0 0 1</normal>
              <size>1 1</size>
            </plane>
          </geometry>
          <surface>
            <friction>
              <ode/>
            </friction>
            <bounce/>
            <contact/>
          </surface>
        </collision>
        <pose>0 0 0 0 -0 0</pose>
        <inertial>
          <pose>0 0 0 0 -0 0</pose>
          <mass>1</mass>
          <inertia>
            <ixx>1</ixx>
            <ixy>0</ixy>
            <ixz>0</ixz>
            <iyy>1</iyy>
            <iyz>0</iyz>
            <izz>1</izz>
          </inertia>
        </inertial>
        <enable_wind>false</enable_wind>
      </link>
      <pose>0 0 0 0 -0 0</pose>
      <self_collide>false</self_collide>
    </model>

    <!-- Jetracer model -->
    <model name="jetracer">
      <pose relative_to="world">0 0 0.01 0 0 0</pose>
      <self_collide>false</self_collide>
      <static>false</static>
     
      <frame name="lidar_frame" attached_to="jetracer/Base">
        <pose>0 0 0.08 0 0 0</pose>
      </frame>

      <link name='jetracer/Base'>
        <pose>0 0 0.033 0 0 0</pose>
        <sensor name="imu_sensor" type="imu">
          <always_on>1</always_on>
          <update_rate>1</update_rate>
          <visualize>true</visualize>
          <topic>imu</topic>
        </sensor>

        <sensor name='gpu_lidar' type='gpu_lidar'>
          <pose relative_to='lidar_frame'>0 0 0 0 0 0</pose>
          <topic>lidar</topic>
          <update_rate>10</update_rate>
          <ray>
            <scan>
              <horizontal>
                <samples>120</samples>
                <resolution>1</resolution>
                <min_angle>-1.0472</min_angle>
                <max_angle>1.0472</max_angle>
              </horizontal>
              <vertical>
                <samples>1</samples>
                <resolution>0.01</resolution>
                <min_angle>0</min_angle>
                <max_angle>0</max_angle>
              </vertical>
            </scan>
            <range>
              <min>0.08</min>
              <max>1.5</max>
              <resolution>0.01</resolution>
            </range>
          </ray>
          <alwaysOn>1</alwaysOn>
          <visualize>true</visualize>
        </sensor>

        <inertial>
          <mass>1.329</mass>
        </inertial>
        <collision name='collision'>
          <geometry>
            <box>
              <size>0.23 0.122 0.02</size>
            </box>
          </geometry>
        </collision>
        <visual name='visual'>
          <geometry>
            <box>
              <size>0.23 0.122 0.02</size>
            </box>
          </geometry>
          <material>
            <ambient>0.0 1.0 0.0 1</ambient>
            <diffuse>0.0 1.0 0.0 1</diffuse>
            <specular>0.0 1.0 0.0 1</specular>
          </material>
        </visual>
      </link>
      <link name="jetracer/FrontRightWheel">
        <pose relative_to="jetracer/FrontRightWheelJoint">0 0 0 0 0 0</pose>
        <inertial>
          <mass>.05</mass>
          <inertia>
            <ixx>0.00003331</ixx>
            <ixy>0</ixy>
            <ixz>0</ixz>
            <iyy>0.0000204</iyy>
            <iyz>0</iyz>
            <izz>0.0000204</izz>
          </inertia>
        </inertial>
        <gravity>true</gravity>
        <velocity_decay/>
        <visual name="jetracer/FrontRightWheelVisual">
          <pose>0 0 0 0 0 0</pose>
          <geometry>
            <mesh>
              <uri>meshes/Wheel.dae</uri>
              <scale>0.9041 0.866 0.9041</scale>
            </mesh>
          </geometry>
        </visual>
        <collision name="jetracer/FrontRightWheelCollision">
          <pose>0 .015 0 -1.5707 0 0</pose>
          <geometry>
            <cylinder>
              <length>0.026</length>
              <radius>0.033</radius>
            </cylinder>
          </geometry>
          <surface>
            <friction>
              <ode>
                <mu>0.5</mu>
                <mu2>1.0</mu2>
                <fdir1>0 0 1</fdir1>
              </ode>
            </friction>
          </surface>
        </collision>
      </link>
      <link name="jetracer/FrontRightWheelSteering">
        <pose relative_to="jetracer/FrontRightWheelSteeringJoint">0 0 0 0 0 0</pose>
        <inertial>
          <mass>0.005</mass>
          <inertia>
            <ixx>0.0000018</ixx>
            <iyy>0.0000018</iyy>
            <izz>0.0000018</izz>
          </inertia>
        </inertial>
      </link>
      <link name="jetracer/FrontLeftWheel">
        <pose relative_to="jetracer/FrontLeftWheelJoint">0 0 0 0 0 0</pose>
        <inertial>
          <mass>.05</mass>
          <inertia>
            <ixx>0.00003331</ixx>
            <ixy>0</ixy>
            <ixz>0</ixz>
            <iyy>0.0000204</iyy>
            <iyz>0</iyz>
            <izz>0.0000204</izz>
          </inertia>
        </inertial>
        <gravity>true</gravity>
        <velocity_decay/>
        <visual name="jetracer/FrontLeftWheelVisual">
          <pose>0 0 0 0 0 3.14159</pose>
          <geometry>
            <mesh>
              <uri>meshes/Wheel.dae</uri>
              <scale>0.9041 0.866 0.9041</scale>
            </mesh>
          </geometry>
        </visual>
        <collision name="jetracer/FrontLeftWheelCollision">
          <pose>0 -.015 0 -1.5707 0 0</pose>
          <geometry>
            <cylinder>
              <length>0.026</length>
              <radius>0.033</radius>
            </cylinder>
          </geometry>
          <surface>
            <friction>
              <ode>
                <mu>0.5</mu>
                <mu2>1.0</mu2>
                <fdir1>0 0 1</fdir1>
              </ode>
            </friction>
          </surface>
        </collision>
      </link>
      <link name="jetracer/FrontLeftWheelSteering">
        <pose relative_to="jetracer/FrontLeftWheelSteeringJoint">0 0 0 0 0 0</pose>
        <inertial>
          <mass>0.005</mass>
          <inertia>
            <ixx>0.0000018</ixx>
            <iyy>0.0000018</iyy>
            <izz>0.0000018</izz>
          </inertia>
        </inertial>
      </link>
      <link name="jetracer/RearRightWheel">
        <pose relative_to="jetracer/RearRightWheelJoint">0 0 0 0 0 0</pose>
        <inertial>
          <mass>.05</mass>
          <inertia>
            <ixx>0.00003331</ixx>
            <ixy>0</ixy>
            <ixz>0</ixz>
            <iyy>0.0000204</iyy>
            <iyz>0</iyz>
            <izz>0.0000204</izz>
          </inertia>
        </inertial>
        <gravity>true</gravity>
        <velocity_decay/>
        <visual name="jetracer/RearRightWheelVisual">
          <pose>0 0 0 0 0 0</pose>
          <geometry>
            <mesh>
              <uri>meshes/Wheel.dae</uri>
              <scale>0.9041 0.866 0.9041</scale>
            </mesh>
          </geometry>
        </visual>
        <collision name="jetracer/RearRightWheelCollision">
          <pose>0 .015 0 -1.5707 0 0</pose>
          <geometry>
            <cylinder>
              <length>0.026</length>
              <radius>0.033</radius>
            </cylinder>
          </geometry>
          <surface>
            <friction>
              <ode>
                <mu>0.5</mu>
                <mu2>1.0</mu2>
                <fdir1>0 0 1</fdir1>
              </ode>
            </friction>
          </surface>
        </collision>
      </link>
      <link name="jetracer/RearLeftWheel">
        <pose relative_to="jetracer/RearLeftWheelJoint">0 0 0 0 0 0</pose>
        <inertial>
          <mass>.05</mass>
          <inertia>
            <ixx>0.00003331</ixx>
            <ixy>0</ixy>
            <ixz>0</ixz>
            <iyy>0.0000204</iyy>
            <iyz>0</iyz>
            <izz>0.0000204</izz>
          </inertia>
        </inertial>
        <gravity>true</gravity>
        <velocity_decay/>
        <visual name="jetracer/RearLeftWheelVisual">
          <pose>0 0 0 0 0 3.14159</pose>
          <geometry>
            <mesh>
              <uri>meshes/Wheel.dae</uri>
              <scale>0.9041 0.866 0.9041</scale>
            </mesh>
          </geometry>
        </visual>
        <collision name="jetracer/RearLeftWheelCollision">
          <pose>0 -.015 0 -1.5707 0 0</pose>
          <geometry>
            <cylinder>
              <length>0.026</length>
              <radius>0.033</radius>
            </cylinder>
          </geometry>
          <surface>
            <friction>
              <ode>
                <mu>0.5</mu>
                <mu2>1.0</mu2>
                <fdir1>0 0 1</fdir1>
              </ode>
            </friction>
          </surface>
        </collision>
      </link>
      <joint name="jetracer/FrontRightWheelSteeringJoint" type="revolute">
        <parent>jetracer/Base</parent>
        <child>jetracer/FrontRightWheelSteering</child>
        <pose relative_to="jetracer/Base">.064 -0.089 0 0 0 0</pose>
        <axis>
          <xyz>0 0 1</xyz>
          <limit>
            <lower>-0.6</lower>
            <upper>0.6</upper>
            <velocity>1.0</velocity>
            <effort>25</effort>
          </limit>
          <use_parent_model_frame>1</use_parent_model_frame>
        </axis>
      </joint>
      <joint name="jetracer/FrontRightWheelJoint" type="revolute">
        <parent>jetracer/FrontRightWheelSteering</parent>
        <child>jetracer/FrontRightWheel</child>
        <pose relative_to="jetracer/FrontRightWheelSteeringJoint">0 0 0 0 0 0</pose>
        <axis>
          <xyz>0 1 0</xyz>
          <limit>
            <lower>-1.79769e+308</lower>
            <upper>1.79769e+308</upper>
          </limit>
          <dynamics>
            <spring_reference>0</spring_reference>
            <spring_stiffness>0</spring_stiffness>
          </dynamics>
          <use_parent_model_frame>1</use_parent_model_frame>
        </axis>
      </joint>
      <joint name="jetracer/FrontLeftWheelSteeringJoint" type="revolute">
        <parent>jetracer/Base</parent>
        <child>jetracer/FrontLeftWheelSteering</child>
        <pose relative_to="jetracer/Base">.064 .089 0 0 0 0</pose>
        <axis>
          <xyz>0 0 1</xyz>
          <limit>
            <lower>-0.6</lower>
            <upper>0.6</upper>
            <velocity>1.0</velocity>
            <effort>25</effort>
          </limit>
          <use_parent_model_frame>1</use_parent_model_frame>
        </axis>
      </joint>
      <joint name="jetracer/FrontLeftWheelJoint" type="revolute">
        <parent>jetracer/FrontLeftWheelSteering</parent>
        <child>jetracer/FrontLeftWheel</child>
        <pose relative_to="jetracer/FrontLeftWheelSteeringJoint">0 0 0 0 0 0</pose>
        <axis>
          <xyz>0 1 0</xyz>
          <limit>
            <lower>-1.79769e+308</lower>
            <upper>1.79769e+308</upper>
          </limit>
          <dynamics>
            <spring_reference>0</spring_reference>
            <spring_stiffness>0</spring_stiffness>
          </dynamics>
          <use_parent_model_frame>1</use_parent_model_frame>
        </axis>
      </joint>
      <joint name="jetracer/RearRightWheelJoint" type="revolute">
        <parent>jetracer/Base</parent>
        <child>jetracer/RearRightWheel</child>
        <pose relative_to="jetracer/Base">-0.088 -0.089 0 0 0 0</pose>
        <axis>
          <xyz>0 1 0</xyz>
          <limit>
            <lower>-1.79769e+308</lower>
            <upper>1.79769e+308</upper>
          </limit>
          <dynamics>
            <spring_reference>0</spring_reference>
            <spring_stiffness>0</spring_stiffness>
          </dynamics>
          <use_parent_model_frame>1</use_parent_model_frame>
        </axis>
      </joint>
      <joint name="jetracer/RearLeftWheelJoint" type="revolute">
        <parent>jetracer/Base</parent>
        <child>jetracer/RearLeftWheel</child>
        <pose relative_to="jetracer/Base">-0.088 0.089 0 0 0 0</pose>
        <axis>
          <xyz>0 1 0</xyz>
          <limit>
            <lower>-1.79769e+308</lower>
            <upper>1.79769e+308</upper>
          </limit>
          <dynamics>
            <spring_reference>0</spring_reference>
            <spring_stiffness>0</spring_stiffness>
          </dynamics>
          <use_parent_model_frame>1</use_parent_model_frame>
        </axis>
      </joint>
      <plugin
        filename="ignition-gazebo-ackermann-steering-system"
        name="ignition::gazebo::systems::AckermannSteering">
        <left_joint>jetracer/FrontLeftWheelJoint</left_joint>
        <left_joint>jetracer/RearLeftWheelJoint</left_joint>
        <right_joint>jetracer/FrontRightWheelJoint</right_joint>
        <right_joint>jetracer/FrontRightWheelJoint</right_joint>
        <left_steering_joint>jetracer/FrontLeftWheelSteeringJoint</left_steering_joint>
        <right_steering_joint>jetracer/FrontRightWheelSteeringJoint</right_steering_joint>
        <kingpin_width>.18</kingpin_width>
        <steering_limit>0.5</steering_limit>
        <wheel_base>.2255</wheel_base>
        <wheel_separation>.2</wheel_separation>
        <wheel_radius>0.0365</wheel_radius>
        <min_velocity>-100</min_velocity>
        <max_velocity>100</max_velocity>
        <min_acceleration>-5</min_acceleration>
        <max_acceleration>5</max_acceleration>
        <topic>/cmd_vel</topic>
      </plugin>
    </model>

    <!-- Keyboard: moving forward -->
    <plugin 
        filename="libignition-gazebo-triggered-publisher-system.so"
        name="ignition::gazebo::systems::TriggeredPublisher">
      <input type="ignition.msgs.Int32" topic="/keyboard/keypress">
        <match field="data">16777235</match> 
      </input>
      <output type="ignition.msgs.Twist" topic="/cmd_vel">
        linear: {x: 0.5}, angular: {z: 0.0}
      </output>
    </plugin>

    <!-- Keyboard: moving backward -->
    <plugin
        filename="libignition-gazebo-triggered-publisher-system.so"
        name="ignition::gazebo::systems::TriggeredPublisher">
      <input type="ignition.msgs.Int32" topic="/keyboard/keypress">
        <match field="data">16777237</match>
      </input>
      <output type="ignition.msgs.Twist" topic="/cmd_vel">
        linear: {x: -0.5}, angular: {z: 0.0}
      </output>
    </plugin>

    <!-- Keyboard: turning left -->
    <plugin
        filename="libignition-gazebo-triggered-publisher-system.so"
        name="ignition::gazebo::systems::TriggeredPublisher">
      <input type="ignition.msgs.Int32" topic="/keyboard/keypress">
        <match field="data">16777234</match>
      </input>
      <output type="ignition.msgs.Twist" topic="/cmd_vel">
        linear: {x: 0.5}, angular: {z: 0.5}
      </output>
    </plugin>

    <!-- Keyboard: turning right -->
    <plugin
        filename="libignition-gazebo-triggered-publisher-system.so"
        name="ignition::gazebo::systems::TriggeredPublisher">
      <input type="ignition.msgs.Int32" topic="/keyboard/keypress">
        <match field="data">16777236</match>
      </input>
      <output type="ignition.msgs.Twist" topic="/cmd_vel">
        linear: {x: 0.5}, angular: {z: -0.5}
      </output>
    </plugin>

    <!-- Keyboard: stop -->
    <plugin
        filename="libignition-gazebo-triggered-publisher-system.so"
        name="ignition::gazebo::systems::TriggeredPublisher">
      <input type="ignition.msgs.Int32" topic="/keyboard/keypress">
        <match field="data">83</match>
      </input>
      <output type="ignition.msgs.Twist" topic="/cmd_vel">
        linear: {x: 0.0}, angular: {z: 0.0}
      </output>
    </plugin>


    <include>
      <uri>https://fuel.ignitionrobotics.org/1.0/OpenRobotics/models/Warehouse</uri>
      <name>warehouse</name>
      <pose>0 0 -0.09 0 -0 0</pose>
    </include>
    <include>
      <uri>https://fuel.ignitionrobotics.org/1.0/MovAi/models/Tugbot-charging-station</uri>
      <name>charging_station</name>
      <pose>14.7 -10.6 -0.04 0 -0 0</pose>
    </include>
    <include>
      <uri>https://fuel.ignitionrobotics.org/1.0/MovAi/models/cart_model_2</uri>
      <name>cart1</name>
      <pose>-5.73 15 0.25 0 -0 0</pose>
    </include>
    <include>
      <uri>https://fuel.ignitionrobotics.org/1.0/MovAi/models/shelf_big</uri>
      <name>shelf_big_0</name>
      <pose>-9.34177 -13.5598 0 0 -0 0</pose>
    </include>
    <include>
      <uri>https://fuel.ignitionrobotics.org/1.0/MovAi/models/shelf</uri>
      <name>shelf</name>
      <pose>-4.41528 -0.690987 0 0 -0 0</pose>
    </include>
    <include>
      <uri>https://fuel.ignitionrobotics.org/1.0/MovAi/models/shelf</uri>
      <name>shelf_0</name>
      <pose>-4.41528 2.30697 0 0 -0 0</pose>
    </include>
    <include>
      <uri>https://fuel.ignitionrobotics.org/1.0/MovAi/models/shelf</uri>
      <name>shelf_1</name>
      <pose>-4.41528 5.30708 0 0 -0 0</pose>
    </include>
    <include>
      <uri>https://fuel.ignitionrobotics.org/1.0/MovAi/models/shelf</uri>
      <name>shelf_2</name>
      <pose>-4.41528 8.34352 0 0 -0 0</pose>
    </include>
    <include>
      <uri>https://fuel.ignitionrobotics.org/1.0/MovAi/models/shelf</uri>
      <name>shelf_3</name>
      <pose>5.60144 8.34352 0 0 -0 0</pose>
    </include>
    <include>
      <uri>https://fuel.ignitionrobotics.org/1.0/MovAi/models/shelf</uri>
      <name>shelf_4</name>
      <pose>5.60144 5.30708 0 0 -0 0</pose>
    </include>
    <include>
      <uri>https://fuel.ignitionrobotics.org/1.0/MovAi/models/shelf</uri>
      <name>shelf_5</name>
      <pose>5.60144 -0.690987 0 0 -0 0</pose>
    </include>
    <include>
      <uri>https://fuel.ignitionrobotics.org/1.0/MovAi/models/shelf</uri>
      <name>shelf_6</name>
      <pose>5.60144 2.30697 0 0 -0 0</pose>
    </include>
    <include>
      <uri>https://fuel.ignitionrobotics.org/1.0/MovAi/models/pallet_box_mobile</uri>
      <name>pallet_box_mobile</name>
      <pose>4.4161 14.6952 0.01 0 -0 0</pose>
    </include>
    <include>
      <uri>https://fuel.ignitionrobotics.org/1.0/MovAi/models/pallet_box_mobile</uri>
      <name>pallet_box_mobile_0</name>
      <pose>4.45415 13.6212 0.01 0 -0 0</pose>
    </include>
    <include>
      <uri>https://fuel.ignitionrobotics.org/1.0/MovAi/models/pallet_box_mobile</uri>
      <name>pallet_box_mobile_1</name>
      <pose>4.4468 12.229 0.01 0 -0 0</pose>
    </include>
    <include>
      <uri>https://fuel.ignitionrobotics.org/1.0/MovAi/models/pallet_box_mobile</uri>
      <name>pallet_box</name>
      <pose>-6.11913 13.7079 0.01 0 -0 0</pose>
    </include>
    <include>
      <uri>https://fuel.ignitionrobotics.org/1.0/MovAi/models/shelf_big</uri>
      <name>shelf_big_1</name>
      <pose>13.9821 15.319 0 0 -0 0</pose>
    </include>
    <include>
      <uri>https://fuel.ignitionrobotics.org/1.0/MovAi/models/shelf_big</uri>
      <name>shelf_big_2</name>
      <pose>6.19777 -12.9647 0 0 -0 0</pose>
    </include>
    <include>
      <uri>https://fuel.ignitionrobotics.org/1.0/MovAi/models/shelf_big</uri>
      <name>shelf_big_3</name>
      <pose>0.594376 -12.9647 0 0 -0 0</pose>
    </include>
    <include>
      <uri>https://fuel.ignitionrobotics.org/1.0/MovAi/models/shelf_big</uri>
      <name>shelf_big_4</name>
      <pose>-5.36284 -12.9647 0 0 -0 0</pose>
    </include>
    <include>
      <uri>https://fuel.ignitionrobotics.org/1.0/MovAi/models/shelf</uri>
      <name>shelf_7</name>
      <pose>13.3818 -21.2416 0 0 -0 0</pose>
    </include>
    <include>
      <uri>https://fuel.ignitionrobotics.org/1.0/MovAi/models/shelf</uri>
      <name>shelf_8</name>
      <pose>13.3818 -19.0028 0 0 -0 0</pose>
    </include>
    <include>
      <uri>https://fuel.ignitionrobotics.org/1.0/MovAi/models/shelf</uri>
      <name>shelf_9</name>
      <pose>13.3818 -16.4478 0 0 -0 0</pose>
    </include>
    <include>
      <uri>https://fuel.ignitionrobotics.org/1.0/MovAi/models/shelf</uri>
      <name>shelf_10</name>
      <pose>13.3818 -14.1028 0 0 -0 0</pose>
    </include>
    <include>
      <uri>https://fuel.ignitionrobotics.org/1.0/MovAi/models/pallet_box_mobile</uri>
      <name>pallet_box_0</name>
      <pose>14.0222 -24.335 0.01 0 -0 0</pose>
    </include>
    <light name='sun' type='directional'>
      <pose>-5 -3 10 0 -0 0</pose>
      <cast_shadows>false</cast_shadows>
      <intensity>1</intensity>
      <direction>0 0 -1</direction>
      <diffuse>1 1 1 1</diffuse>
      <specular>1 1 1 1</specular>
      <attenuation>
        <range>10</range>
        <linear>1</linear>
        <constant>1</constant>
        <quadratic>0</quadratic>
      </attenuation>
      <spot>
        <inner_angle>0</inner_angle>
        <outer_angle>0</outer_angle>
        <falloff>0</falloff>
      </spot>
    </light>
  </world>
</sdf>
